<mujoco model="robot">
  <compiler angle="radian" meshdir="assets" autolimits="true"/>

  <option integrator="RK4" cone="elliptic" impratio="10"/>

  <default>
    <default class="robot">
      <material specular="0.5" shininess="0.25"/>
      <joint axis="0 1 0" range="-6.28319 6.28319" armature="0.1"/>
      <position ctrlrange="-6.2831 6.2831"/>
      <general biastype="affine" ctrlrange="-6.2831 6.2831" gainprm="5000" biasprm="0 -5000 -500"/>
      <default class="size4">
        <joint damping="10"/>
        <general forcerange="-330 330"/>
      </default>
      <default class="size3">
        <joint damping="5"/>
        <general forcerange="-150 150"/>
        <default class="size3_limited">
          <joint range="-3.1415 3.1415"/>
          <general ctrlrange="-3.1415 3.1415"/>
        </default>
      </default>
      <default class="size2">
        <joint damping="2"/>
        <general forcerange="-56 56"/>
      </default>
      <default class="visual_ur">
        <geom type="mesh" contype="0" conaffinity="0" group="2"/>
      </default>
      <default class="collision_ur">
        <geom type="capsule" group="3"/>
        <default class="eef_collision">
          <geom type="cylinder"/>
        </default>
      </default>
      <site size="0.001" rgba="0.5 0.5 0.5 0.3" group="4"/>

      <default class="2f85">
        <mesh scale="0.001 0.001 0.001"/>
        <general biastype="affine"/>

        <joint axis="0 0 1"/>
        <default class="driver">
          <joint range="0 0.9" armature="0.005" damping="0.1" solimplimit="0.95 0.99 0.001" solreflimit="0.005 1"/>
        </default>
        <default class="follower">
          <joint range="-0.872664 0.9" armature="0.001"  solimplimit="0.95 0.99 0.001" solreflimit="0.005 1"/>
        </default>
        <default class="spring_link">
          <joint range="-0.29670597283 0.9" armature="0.001" stiffness="0.05" springref="2.62" damping="0.00125"/>
        </default>
        <default class="coupler">
          <joint range="-1.57 0" armature="0.001" solimplimit="0.95 0.99 0.001" solreflimit="0.005 1"/>
        </default>

        <default class="visual">
          <geom type="mesh" contype="0" conaffinity="0" group="2" material="black"/>
        </default>
        <default class="collision">
          <geom type="mesh" group="3"/>
          <default class="pad_box1">
            <geom type="box" pos="0.043258  0 0.12"  size="0.002 0.011 0.009375" friction="0.7"
              solref="0.004 1" solimp="0.95 0.99 0.001" priority="1" rgba="0.55 0.55 0.55 1"/>
          </default>
          <default class="pad_box2">
            <geom type="box" pos="0.043258 0 0.13875" size="0.002 0.011 0.009375" friction="0.6"
              solref="0.004 1" solimp="0.95 0.99 0.001" priority="1" rgba="0.45 0.45 0.45 1"/>
          </default>
        </default>
      </default>
      
    </default>
  </default>

  <asset>
    <material class="robot" name="black" rgba="0.033 0.033 0.033 1"/>
    <material class="robot" name="jointgray" rgba="0.278 0.278 0.278 1"/>
    <material class="robot" name="linkgray" rgba="0.82 0.82 0.82 1"/>
    <material class="robot" name="urblue" rgba="0.49 0.678 0.8 1"/>

    <mesh file="ur10e/base_0.obj"/>
    <mesh file="ur10e/base_1.obj"/>
    <mesh file="ur10e/shoulder_0.obj"/>
    <mesh file="ur10e/shoulder_1.obj"/>
    <mesh file="ur10e/shoulder_2.obj"/>
    <mesh file="ur10e/upperarm_0.obj"/>
    <mesh file="ur10e/upperarm_1.obj"/>
    <mesh file="ur10e/upperarm_2.obj"/>
    <mesh file="ur10e/upperarm_3.obj"/>
    <mesh file="ur10e/forearm_0.obj"/>
    <mesh file="ur10e/forearm_1.obj"/>
    <mesh file="ur10e/forearm_2.obj"/>
    <mesh file="ur10e/forearm_3.obj"/>
    <mesh file="ur10e/wrist1_0.obj"/>
    <mesh file="ur10e/wrist1_1.obj"/>
    <mesh file="ur10e/wrist1_2.obj"/>
    <mesh file="ur10e/wrist2_0.obj"/>
    <mesh file="ur10e/wrist2_1.obj"/>
    <mesh file="ur10e/wrist2_2.obj"/>
    <mesh file="ur10e/wrist3.obj"/>

    <material name="metal" rgba="0.58 0.58 0.58 1"/>
    <!-- <material name="silicone" rgba="0.1882 0.1882 0.1882 1"/>
    <material name="black" rgba="0.149 0.149 0.149 1"/> -->

    <mesh file="2f85/base.stl"/>
    <mesh file="2f85/base_coupling.stl"/>
    <mesh file="2f85/c-a01-85-open.stl"/>
    <mesh file="2f85/driver.stl"/>
    <mesh file="2f85/coupler.stl"/>
    <mesh file="2f85/spring_link.stl"/>
    <mesh file="2f85/follower.stl"/>
    <mesh file="2f85/tongue.stl"/>
  </asset>

  <worldbody>
    <light name="spotlight" mode="targetbodycom" target="wrist_2_link" pos="0 -1 2"/>
    <body name="base" quat="0 0 0 -1" childclass="robot">
      <inertial mass="4.0" pos="0 0 0" diaginertia="0.0061063308908 0.0061063308908 0.01125"/>
      <geom mesh="base_0" material="black" class="visual_ur"/>
      <geom mesh="base_1" material="jointgray" class="visual_ur"/>
      <body name="shoulder_link" pos="0 0 0.181">
        <inertial pos="0 0 0" mass="7.778" diaginertia="0.0314743 0.0314743 0.0218756"/>
        <joint name="shoulder_pan_joint" class="size4" axis="0 0 1"/>
        <geom mesh="shoulder_0" material="urblue" class="visual_ur"/>
        <geom mesh="shoulder_1" material="black" class="visual_ur"/>
        <geom mesh="shoulder_2" material="jointgray" class="visual_ur"/>
        <geom class="collision_ur" size="0.078 0.08" pos="0 0 -0.05"/>
        <body name="upper_arm_link" pos="0 0.176 0" quat="1 0 1 0">
          <inertial pos="0 0 0.3065" mass="12.93" diaginertia="0.423074 0.423074 0.0363656"/>
          <joint name="shoulder_lift_joint" class="size4"/>
          <geom mesh="upperarm_0" material="black" class="visual_ur"/>
          <geom mesh="upperarm_1" material="jointgray" class="visual_ur"/>
          <geom mesh="upperarm_2" material="urblue" class="visual_ur"/>
          <geom mesh="upperarm_3" material="linkgray" class="visual_ur"/>
          <geom class="collision_ur" pos="0 -0.05 0" quat="1 1 0 0" size="0.078 0.08"/>
          <geom class="collision_ur" size="0.06 0.3" pos="0 0 0.3"/>
          <body name="forearm_link" pos="0 -0.137 0.613">
            <inertial pos="0 0 0.2855" mass="3.87" diaginertia="0.11059 0.11059 0.0108844"/>
            <joint name="elbow_joint" class="size3_limited"/>
            <geom mesh="forearm_0" material="urblue" class="visual_ur"/>
            <geom mesh="forearm_1" material="black" class="visual_ur"/>
            <geom mesh="forearm_2" material="jointgray" class="visual_ur"/>
            <geom mesh="forearm_3" material="linkgray" class="visual_ur"/>
            <geom class="collision_ur" pos="0 0.08 0" quat="1 1 0 0" size="0.058 0.065"/>
            <geom class="collision_ur" size="0.043 0.28" pos="0 0 0.29"/>
            <body name="wrist_1_link" pos="0 0 0.571" quat="1 0 1 0">
              <inertial pos="0 0.135 0" quat="0.5 0.5 -0.5 0.5" mass="1.96"
                diaginertia="0.0055125 0.00510825 0.00510825"/>
              <joint name="wrist_1_joint" class="size2"/>
              <geom mesh="wrist1_0" material="black" class="visual_ur"/>
              <geom mesh="wrist1_1" material="urblue" class="visual_ur"/>
              <geom mesh="wrist1_2" material="jointgray" class="visual_ur"/>
              <geom class="collision_ur" pos="0 0.06 0" quat="1 1 0 0" size="0.05 0.07"/>
              <body name="wrist_2_link" pos="0 0.135 0">
                <inertial pos="0 0 0.12" quat="0.5 0.5 -0.5 0.5" mass="1.96"
                  diaginertia="0.0055125 0.00510825 0.00510825"/>
                <joint name="wrist_2_joint" axis="0 0 1" class="size2"/>
                <geom mesh="wrist2_0" material="black" class="visual_ur"/>
                <geom mesh="wrist2_1" material="urblue" class="visual_ur"/>
                <geom mesh="wrist2_2" material="jointgray" class="visual_ur"/>
                <geom class="collision_ur" size="0.046 0.065" pos="0 0 0.05"/>
                <geom class="collision_ur" pos="0 0.028 0.12" quat="1 1 0 0" size="0.046 0.043"/>
                <body name="wrist_3_link" pos="0 0 0.12">
                  <inertial pos="0 0.092 0" quat="0 1 -1 0" mass="0.202"
                    diaginertia="0.000204525 0.000144346 0.000144346"/>
                  <joint name="wrist_3_joint" class="size2"/>
                  <geom material="linkgray" mesh="wrist3" class="visual_ur"/>
                  <geom class="eef_collision" pos="0 0.097 0" quat="1 1 0 0" size="0.046 0.02"/>
                  <site name="attachment_site" pos="0 0.1 0" quat="-1 1 0 0"/>

                  <body name="gripper_base" childclass="2f85" pos="0.0 0.11 0.0" quat="-1 1 -1 -1">
                    <camera name="cam_gripper" pos="0.0 0.1 0.0" quat="0.0000 0.0000 0.9659 0.2588" fovy="45"/>

                    <inertial mass="0.777441" pos="7.77116e-05 8.42713e-05 0.0311656"
                      quat="0.704758 -0.00373684 -0.00570287 0.709415"
                      diaginertia="0.000260285 0.000225381 0.000152708"/>
                    <geom class="visual" pos="0 0 0.0108" quat="0 0 0 1"   mesh="base"/>
                    <geom class="visual" pos="0 0 0.004" quat="1 -1 0 0"   mesh="base_coupling"/>
                    <geom class="visual" pos="0 0 0.0108" quat="1 0 0 0"  material="metal" mesh="c-a01-85-open"/>
                    <geom class="collision" mesh="base"/>
                    <!-- Left-hand side 4-bar linkage -->
                    <body name="left_driver" pos="-0.0306011 0.00475 0.0657045" quat="1 -1 0 0">
                      <inertial mass="0.00899563" pos="-0.0175297 0.00165308 -0.00469625"
                          quat="-0.469642 0.469642 -0.528617 0.528617"
                          diaginertia="1.72352e-06 1.60906e-06 3.22006e-07"/>
                      <joint name="left_driver_joint" class="driver"/>
                      <geom class="visual" pos="0.0306011 0.0549045 -0.0047" quat="1 1 0 0"  material="metal" mesh="driver"/>
                      <geom class="collision" pos="0.0306011 0.0549045 -0.0047" quat="1 1 0 0"   mesh="driver"/>
                      <body name="left_coupler" pos="-0.0314249 0.00453223 -0.0102" quat="0 0 0 1">
                        <inertial mass="0.0140974" pos="0.00367747 0.01986 0.0055"
                          quat="0.701447 -0.701447 0.0892884 -0.0892884"
                          diaginertia="4.16206e-06 3.52216e-06 8.88131e-07"/>
                        <geom class="visual" pos="-0.062026 -0.0503723 0.0055" quat="1 -1 0 0"   mesh="coupler"/>
                        <geom class="collision" pos="-0.062026 -0.0503723 0.0055" quat="1 -1 0 0"  mesh="coupler"/>
                      </body>
                    </body>
                    <body name="left_spring_link" pos="-0.0127 -0.012 0.07222" quat="1 -1 0 0">
                      <inertial mass="0.0221642" pos="-0.0183 -0.0205732 0.01205"
                          quat="0.660941 0.660941 -0.251309 -0.251309"
                          diaginertia="8.96853e-06 6.71733e-06 2.63931e-06"/>
                      <joint name="left_spring_link_joint" class="spring_link"/>
                      <geom class="visual" pos="0.0127 0.06142 0.01205" quat="1 1 0 0" type="mesh"  mesh="spring_link"/>
                      <geom class="collision" pos="0.0127 0.06142 0.01205" quat="1 1 0 0" type="mesh"  mesh="spring_link"/>
                      <body name="left_follower" pos="-0.0382079 -0.0425003 0.00295" quat="0 -1 -1.90231e-05 0">
                        <inertial mass="0.0125222" pos="-0.00852976 -0.0014822 -0.00910001"
                          quat="0.359439 0.359439 0.608937 0.608937"
                          diaginertia="2.67415e-06 2.4559e-06 6.02031e-07"/>
                        <joint name="left_follower" class="follower"/>
                        <geom class="visual" pos="0.0509079 -0.10392 -0.0091" quat="1 -1 0 0" type="mesh"  mesh="follower"/>
                        <geom class="visual" pos="0.0509079 -0.10392 -0.0091" quat="1 -1 0 0" type="mesh" material="metal" mesh="tongue"/>
                        <geom class="collision" pos="0.0509079 -0.10392 -0.0091" quat="1 -1 0 0" type="mesh"  mesh="follower"/>
                        <geom class="collision" pos="0.0509079 -0.10392 -0.0091" quat="1 -1 0 0" type="mesh"  mesh="tongue"/>
                        <body name="left_pad" pos="-0.0377897 -0.103916 -0.0091" quat="1 -1 0 0" >
                          <geom class="pad_box1" name="left_pad1"/>
                          <geom class="pad_box2" name="left_pad2"/>
                        </body>
                      </body>
                    </body>
                    <!-- Right-hand side 4-bar linkage -->
                    <body name="right_driver" pos="0.0306011 -0.00475 0.0657045" quat="0 0 -1 1">
                      <inertial mass="0.00899563" pos="-0.0175297 0.00165308 -0.00469625"
                          quat="-0.469642 0.469642 -0.528617 0.528617"
                          diaginertia="1.72352e-06 1.60906e-06 3.22006e-07"/>
                      <joint name="right_driver_joint" class="driver"/>
                      <geom class="visual" pos="0.0306011 0.0549045 -0.0047" quat="1 1 0 0" material="metal" mesh="driver"/>
                      <geom class="collision" pos="0.0306011 0.0549045 -0.0047" quat="1 1 0 0"  mesh="driver"/>
                      <body name="right_coupler" pos="-0.0314249 0.00453223 -0.0102" quat="0 0 0 1">
                        <inertial mass="0.0140974" pos="0.00367747 0.01986 0.0055"
                          quat="0.701447 -0.701447 0.0892884 -0.0892884"
                          diaginertia="4.16206e-06 3.52216e-06 8.88131e-07"/>
                        <geom class="visual" pos="-0.062026 -0.0503723 0.0055" quat="1 -1 0 0"   mesh="coupler"/>
                        <geom class="collision" pos="-0.062026 -0.0503723 0.0055" quat="1 -1 0 0"   mesh="coupler"/>
                      </body>
                    </body>
                    <body name="right_spring_link" pos="0.0127 0.012 0.07222" quat="0 0 -1 1">
                      <inertial mass="0.0221642" pos="-0.0183 -0.0205732 0.01205"
                          quat="0.660941 0.660941 -0.251309 -0.251309"
                          diaginertia="8.96853e-06 6.71733e-06 2.63931e-06"/>
                      <joint name="right_spring_link_joint" class="spring_link"/>
                      <geom class="visual" pos="0.0127 0.06142 0.01205" quat="1 1 0 0"   mesh="spring_link"/>
                      <geom class="collision" pos="0.0127 0.06142 0.01205" quat="1 1 0 0"   mesh="spring_link"/>
                      <body name="right_follower" pos="-0.0382079 -0.0425003 0.00295" quat="0 -1 0 0">
                        <inertial mass="0.0125222" pos="-0.00852976 -0.0014822 -0.00910001"
                          quat="0.359439 0.359439 0.608937 0.608937"
                          diaginertia="2.67415e-06 2.4559e-06 6.02031e-07"/>
                        <joint name="right_follower_joint" class="follower"/>
                        <geom class="visual" pos="0.0509079 -0.10392 -0.0091" quat="1 -1 0 0"  material="metal" mesh="tongue"/>
                        <geom class="visual" pos="0.0509079 -0.10392 -0.0091" quat="1 -1 0 0"   mesh="follower"/>
                        <geom class="collision" pos="0.0509079 -0.10392 -0.0091" quat="1 -1 0 0"   mesh="tongue"/>
                        <geom class="collision" pos="0.0509079 -0.10392 -0.0091" quat="1 -1 0 0"   mesh="follower"/>
                        <body name="right_pad" pos="-0.0377897 -0.103916 -0.0091"   quat="1 -1 0 0" >
                          <geom class="pad_box1" name="right_pad1"/>
                          <geom class="pad_box2" name="right_pad2"/>
                        </body>
                      </body>
                    </body>
                  </body>
                </body>
              </body>
            </body>
          </body>
        </body>
      </body>
    </body>
  </worldbody>

  <contact>
    <exclude body1="base" body2="left_driver"/>
    <exclude body1="base" body2="right_driver"/>
    <exclude body1="base" body2="left_spring_link"/>
    <exclude body1="base" body2="right_spring_link"/>
    <exclude body1="right_coupler" body2="right_follower"/>
    <exclude body1="left_coupler" body2="left_follower"/>
  </contact>

  <!--
    This adds stability to the model by having a tendon that distributes the forces between both
    joints, such that the equality constraint doesn't have to do that much work in order to equalize
    both joints. Since both joints share the same sign, we split the force between both equally by
    setting coef=0.485
  -->
  <tendon>
    <fixed name="split">
      <joint joint="right_driver_joint" coef="0.485"/>
      <joint joint="left_driver_joint" coef="0.485"/>
    </fixed>
  </tendon>

  <equality>
    <connect anchor="-0.0179014 -0.00651468 0.0044" body1="right_follower" body2="right_coupler" solimp="0.95 0.99 0.001" solref="0.01 1"/>
    <connect anchor="-0.0179014 -0.00651468 0.0044" body1="left_follower" body2="left_coupler" solimp="0.95 0.99 0.001" solref="0.01 1"/>
    <joint joint1="right_driver_joint" joint2="left_driver_joint" polycoef="0 1 0 0 0" solimp="0.95 0.99 0.001"
    solref="0.01 1"/>
  </equality>

  <actuator>
    <general class="size4" name="shoulder_pan" joint="shoulder_pan_joint"/>
    <general class="size4" name="shoulder_lift" joint="shoulder_lift_joint"/>
    <general class="size3_limited" name="elbow" joint="elbow_joint"/>
    <general class="size2" name="wrist_1" joint="wrist_1_joint"/>
    <general class="size2" name="wrist_2" joint="wrist_2_joint"/>
    <general class="size2" name="wrist_3" joint="wrist_3_joint"/>

    <general class="2f85" name="fingers_actuator" tendon="split" forcerange="-5 5" ctrlrange="0 255"
      gainprm="0.3137255 0 0" biasprm="0 -100 -10"/>
  </actuator>

  <!-- <keyframe>
    <key name="home" qpos="-1.5708 -1.5708 1.5708 -1.5708 -1.5708 0" 
                    ctrl="-1.5708 -1.5708 1.5708 -1.5708 -1.5708 0"/>
  </keyframe> -->
</mujoco>
